Workbook

Sheet Question Bank
A1: Question ID | B1: Grade | C1: Part No. | D1: Part | E1: Part ID | F1: Section No. | G1: Section | H1: Section ID | I1: Topic ID | J1: Topic | K1: Question Sequence No. | L1: Learning Objective | M1: Question Type | N1: Question Category | O1: Difficulty | P1: Question Format | Q1: Visual Required | R1: Image Description | S1: Canva Prompt | T1: Bloom's Level | U1: Question | V1: Option A | W1: Option B | X1: Option C | Y1: Option D | Z1: Correct Option | AA1: Explanation | AB1: Future Ready Insight | AC1: Competency Assessed | AD1: Image File | AE1: Reviewer Comments | AF1: Reviewer Name | AG1: Review Date | AH1: Version
A2: 08_EM_OS_001 | B2: 8 | C2: 1 | D2: Entrepreneurship Mindset | E2: EM | F2: 1 | G2: Opportunity Spotting | H2: OS | I2: OS-T01 | J2: =Legacy_Backup!G2 -> Opportunity Spotting | K2: =TEXT(COUNTIF($E$2:E2,E2),"000") -> 001 | L2: =Legacy_Backup!H2 -> Identify useful opportunities from everyday problems | M2: =IFERROR(__xludf.DUMMYFUNCTION("IF(REGEXMATCH(UPPER(Legacy_Backup!I2),""KNOW""),""Know"",IF(REGEXMATCH(UPPER(Legacy_Backup!I2),""IMAGINE|INNOVATION""),""Imagine"",""Think""))"),"Think") -> Think | N2: =IFERROR(__xludf.DUMMYFUNCTION("IF(REGEXMATCH(UPPER(Legacy_Backup!J2),""FUTURE""),""Future-Oriented"",IF(REGEXMATCH(UPPER(Legacy_Backup!J2),""KNOWLEDGE""),""Knowledge-Based"",IF(REGEXMATCH(UPPER(Legacy_Backup!J2),""DECISION""),""Decision-Making"",""Situation-Based"")))"),"Situation-Based") -> Situation-Based | O2: =IF(UPPER(Legacy_Backup!K2)="HARD","Difficult",PROPER(Legacy_Backup!K2)) -> Easy | P2: =IF(UPPER(Legacy_Backup!O2)="YES","Visual","Text") -> Text | Q2: =PROPER(Legacy_Backup!O2) -> No | R2: =IF(UPPER(Legacy_Backup!O2)="YES",IF(Legacy_Backup!Y2<>"",Legacy_Backup!Y2,"Image required"),"NA") -> NA | S2: =IF(UPPER(Legacy_Backup!O2)="YES",IF(Legacy_Backup!Z2<>"",Legacy_Backup!Z2,"Prompt required"),"NA") -> NA | T2: =IF(Legacy_Backup!L2<>"",PROPER(Legacy_Backup!L2),"Apply") -> Apply | U2: =Legacy_Backup!P2 -> A school canteen has long queues and students often miss part of lunch. Which idea best turns this problem into an opportunity? | V2: =Legacy_Backup!Q2 -> Start a pre-order system for students | W2: =Legacy_Backup!R2 -> Sell more items only after lunch | X2: =Legacy_Backup!S2 -> Ask students to bring food every day | Y2: =Legacy_Backup!T2 -> Close one counter to reduce confusion | Z2: =Legacy_Backup!U2 -> A | AA2: =Legacy_Backup!W2 -> Start a pre-order system with fixed pickup slots is the best choice because it directly applies opportunity spotting to the situation and addresses the stated need with a practical, responsible action. | AB2: =Legacy_Backup!X2 -> Builds practical entrepreneurship for future study, work and responsible citizenship. | AC2: =Legacy_Backup!M2 -> Entrepreneurship | AD2: =IF(UPPER(Legacy_Backup!O2)="YES",A2&".png","NA") -> NA | AE2: =Legacy_Backup!AB2 | AH2: =IF(LEFT(Legacy_Backup!AC2,1)="v",Legacy_Backup!AC2,"v"&Legacy_Backup!AC2) -> v1.0
A3: 08_EM_CE_002 | B3: 8 | C3: 1 | D3: Entrepreneurship Mindset | E3: EM | F3: 6 | G3: Customer Understanding and Empathy | H3: CE | I3: CE-T01 | J3: =Legacy_Backup!G3 -> Customer Understanding | K3: =TEXT(COUNTIF($E$2:E3,E3),"000") -> 002 | L3: =Legacy_Backup!H3 -> Use customer feedback before designing a solution | M3: =IFERROR(__xludf.DUMMYFUNCTION("IF(REGEXMATCH(UPPER(Legacy_Backup!I3),""KNOW""),""Know"",IF(REGEXMATCH(UPPER(Legacy_Backup!I3),""IMAGINE|INNOVATION""),""Imagine"",""Think""))"),"Think") -> Think | N3: =IFERROR(__xludf.DUMMYFUNCTION("IF(REGEXMATCH(UPPER(Legacy_Backup!J3),""FUTURE""),""Future-Oriented"",IF(REGEXMATCH(UPPER(Legacy_Backup!J3),""KNOWLEDGE""),""Knowledge-Based"",IF(REGEXMATCH(UPPER(Legacy_Backup!J3),""DECISION""),""Decision-Making"",""Situation-Based"")))"),"Situation-Based") -> Situation-Based | O3: =IF(UPPER(Legacy_Backup!K3)="HARD","Difficult",PROPER(Legacy_Backup!K3)) -> Easy | P3: =IF(UPPER(Legacy_Backup!O3)="YES","Visual","Text") -> Text | Q3: =PROPER(Legacy_Backup!O3) -> No | R3: =IF(UPPER(Legacy_Backup!O3)="YES",IF(Legacy_Backup!Y3<>"",Legacy_Backup!Y3,"Image required"),"NA") -> NA | S3: =IF(UPPER(Legacy_Backup!O3)="YES",IF(Legacy_Backup!Z3<>"",Legacy_Backup!Z3,"Prompt required"),"NA") -> NA | T3: =IF(Legacy_Backup!L3<>"",PROPER(Legacy_Backup!L3),"Apply") -> Analyze | U3: =Legacy_Backup!P3 -> Riya wants to sell reusable water bottles at school. What should she do first? | V3: =Legacy_Backup!Q3 -> Order 200 bottles in her favourite colour | W3: =Legacy_Backup!R3 -> Ask students about their preferences /liking | X3: =Legacy_Backup!S3 -> Copy the most expensive bottle online | Y3: =Legacy_Backup!T3 -> Print posters before deciding the product | Z3: =Legacy_Backup!U3 -> B | AA3: =Legacy_Backup!W3 -> Ask students about size, price and features they prefer is the best choice because it directly applies customer understanding to the situation and addresses the stated need with a practical, responsible action. | AB3: =Legacy_Backup!X3 -> Builds practical entrepreneurship for future study, work and responsible citizenship. | AC3: =Legacy_Backup!M3 -> Entrepreneurship | AD3: =IF(UPPER(Legacy_Backup!O3)="YES",A3&".png","NA") -> NA | AE3: =Legacy_Backup!AB3 | AH3: =IF(LEFT(Legacy_Backup!AC3,1)="v",Legacy_Backup!AC3,"v"&Legacy_Backup!AC3) -> v1.0
A4: 08_EM_PR_003 | B4: 8 | C4: 1 | D4: Entrepreneurship Mindset | E4: EM | F4: 4 | G4: Planning and Resource Use | H4: PR | I4: PR-T01 | J4: =Legacy_Backup!G4 -> Planning and Resource Use | K4: =TEXT(COUNTIF($E$2:E4,E4),"000") -> 003 | L4: =Legacy_Backup!H4 -> Select a plan that uses limited resources wisely | M4: =IFERROR(__xludf.DUMMYFUNCTION("IF(REGEXMATCH(UPPER(Legacy_Backup!I4),""KNOW""),""Know"",IF(REGEXMATCH(UPPER(Legacy_Backup!I4),""IMAGINE|INNOVATION""),""Imagine"",""Think""))"),"Think") -> Think | N4: =IFERROR(__xludf.DUMMYFUNCTION("IF(REGEXMATCH(UPPER(Legacy_Backup!J4),""FUTURE""),""Future-Oriented"",IF(REGEXMATCH(UPPER(Legacy_Backup!J4),""KNOWLEDGE""),""Knowledge-Based"",IF(REGEXMATCH(UPPER(Legacy_Backup!J4),""DECISION""),""Decision-Making"",""Situation-Based"")))"),"Situation-Based") -> Situation-Based | O4: =IF(UPPER(Legacy_Backup!K4)="HARD","Difficult",PROPER(Legacy_Backup!K4)) -> Easy | P4: =IF(UPPER(Legacy_Backup!O4)="YES","Visual","Text") -> Visual | Q4: =PROPER(Legacy_Backup!O4) -> Yes | R4: =IF(UPPER(Legacy_Backup!O4)="YES",IF(Legacy_Backup!Y4<>"",Legacy_Backup!Y4,"Image required"),"NA") -> A clean Grade 8 educational table or chart illustrating: Four teams need the art room. The booking chart shows: Monday 2 teams, Tuesday 1, Wednesday 0, Thursday 3. Which day gives a new team the best chance to work without delay? | S4: =IF(UPPER(Legacy_Backup!O4)="YES",IF(Legacy_Backup!Z4<>"",Legacy_Backup!Z4,"Prompt required"),"NA") -> Create a clear, age-appropriate educational visual for Grade 8. Show only the information needed for this MCQ: Four teams need the art room. The booking chart shows: Monday 2 teams, Tuesday 1, Wednesday 0, Thursday 3. Which day gives a new team the best chance to work without delay? Use a light background, simple labels, high contrast, no answer clues, landscape 4:3. | T4: =IF(Legacy_Backup!L4<>"",PROPER(Legacy_Backup!L4),"Apply") -> Analyze | U4: =Legacy_Backup!P4 -> Four teams need the art room. Refer to the chart showing booking data. Which day gives a new team the best chance to work without delay? | V4: =Legacy_Backup!Q4 -> Monday | W4: =Legacy_Backup!R4 -> Tuesday | X4: =Legacy_Backup!S4 -> Wednesday | Y4: =Legacy_Backup!T4 -> Thursday | Z4: =Legacy_Backup!U4 -> C | AA4: =Legacy_Backup!W4 -> Wednesday is the best choice because it directly applies planning and resource use to the situation and addresses the stated need with a practical, responsible action. | AB4: =Legacy_Backup!X4 -> Builds practical entrepreneurship for future study, work and responsible citizenship. | AC4: =Legacy_Backup!M4 -> Entrepreneurship | AD4: =IF(UPPER(Legacy_Backup!O4)="YES",A4&".png","NA") -> 08_EM_PR_003.png | AE4: =Legacy_Backup!AB4 | AH4: =IF(LEFT(Legacy_Backup!AC4,1)="v",Legacy_Backup!AC4,"v"&Legacy_Backup!AC4) -> v1.0
A5: 08_EM_CE_004 | B5: 8 | C5: 1 | D5: Entrepreneurship Mindset | E5: EM | F5: 6 | G5: Customer Understanding and Empathy | H5: CE | I5: CE-T02 | J5: =Legacy_Backup!G5 -> Value Proposition | K5: =TEXT(COUNTIF($E$2:E5,E5),"000") -> 004 | L5: =Legacy_Backup!H5 -> Connect a product benefit to a customer need | M5: =IFERROR(__xludf.DUMMYFUNCTION("IF(REGEXMATCH(UPPER(Legacy_Backup!I5),""KNOW""),""Know"",IF(REGEXMATCH(UPPER(Legacy_Backup!I5),""IMAGINE|INNOVATION""),""Imagine"",""Think""))"),"Think") -> Think | N5: =IFERROR(__xludf.DUMMYFUNCTION("IF(REGEXMATCH(UPPER(Legacy_Backup!J5),""FUTURE""),""Future-Oriented"",IF(REGEXMATCH(UPPER(Legacy_Backup!J5),""KNOWLEDGE""),""Knowledge-Based"",IF(REGEXMATCH(UPPER(Legacy_Backup!J5),""DECISION""),""Decision-Making"",""Situation-Based"")))"),"Situation-Based") -> Situation-Based | O5: =IF(UPPER(Legacy_Backup!K5)="HARD","Difficult",PROPER(Legacy_Backup!K5)) -> Easy | P5: =IF(UPPER(Legacy_Backup!O5)="YES","Visual","Text") -> Visual | Q5: =PROPER(Legacy_Backup!O5) -> Yes | R5: =IF(UPPER(Legacy_Backup!O5)="YES",IF(Legacy_Backup!Y5<>"",Legacy_Backup!Y5,"Image required"),"NA") -> A clean Grade 8 educational real-life scene illustrating: An image shows two lunch boxes: Box P is stylish but leaks; Box Q is simple, leak-proof and easy to clean. Which is the stronger value proposition for students? | S5: =IF(UPPER(Legacy_Backup!O5)="YES",IF(Legacy_Backup!Z5<>"",Legacy_Backup!Z5,"Prompt required"),"NA") -> Create a clear, age-appropriate educational visual for Grade 8. Show only the information needed for this MCQ: An image shows two lunch boxes: Box P is stylish but leaks; Box Q is simple, leak-proof and easy to clean. Which is the stronger value proposition for students? Use a light background, simple labels, high contrast, no answer clues, landscape 4:3. | T5: =IF(Legacy_Backup!L5<>"",PROPER(Legacy_Backup!L5),"Apply") -> Analyze | U5: =Legacy_Backup!P5 -> An image shows two lunch boxes: Box P & Box Q . Which is the stronger value proposition for students to use? | V5: =Legacy_Backup!Q5 -> Box P, because style is always most important | W5: =Legacy_Backup!R5 -> Box P, because cleaning does not matter | X5: =Legacy_Backup!S5 -> Both are equal because they hold food | Y5: =Legacy_Backup!T5 -> Box Q, because it solves practical daily problems of leakage | Z5: =Legacy_Backup!U5 -> D | AA5: =Legacy_Backup!W5 -> Box Q, because it solves practical daily problems is the best choice because it directly applies value proposition to the situation and addresses the stated need with a practical, responsible action. | AB5: =Legacy_Backup!X5 -> Builds practical entrepreneurship for future study, work and responsible citizenship. | AC5: =Legacy_Backup!M5 -> Entrepreneurship | AD5: =IF(UPPER(Legacy_Backup!O5)="YES",A5&".png","NA") -> 08_EM_CE_004.png | AE5: =Legacy_Backup!AB5 | AH5: =IF(LEFT(Legacy_Backup!AC5,1)="v",Legacy_Backup!AC5,"v"&Legacy_Backup!AC5) -> v1.0
A6: 08_EM_RD_005 | B6: 8 | C6: 1 | D6: Entrepreneurship Mindset | E6: EM | F6: 3 | G6: Risk-Taking and Decision Making | H6: RD | I6: RD-T01 | J6: =Legacy_Backup!G6 -> Risk and Decision Making | K6: =TEXT(COUNTIF($E$2:E6,E6),"000") -> 005 | L6: =Legacy_Backup!H6 -> Reduce risk through a small test | M6: =IFERROR(__xludf.DUMMYFUNCTION("IF(REGEXMATCH(UPPER(Legacy_Backup!I6),""KNOW""),""Know"",IF(REGEXMATCH(UPPER(Legacy_Backup!I6),""IMAGINE|INNOVATION""),""Imagine"",""Think""))"),"Think") -> Think | N6: =IFERROR(__xludf.DUMMYFUNCTION("IF(REGEXMATCH(UPPER(Legacy_Backup!J6),""FUTURE""),""Future-Oriented"",IF(REGEXMATCH(UPPER(Legacy_Backup!J6),""KNOWLEDGE""),""Knowledge-Based"",IF(REGEXMATCH(UPPER(Legacy_Backup!J6),""DECISION""),""Decision-Making"",""Situation-Based"")))"),"Situation-Based") -> Situation-Based | O6: =IF(UPPER(Legacy_Backup!K6)="HARD","Difficult",PROPER(Legacy_Backup!K6)) -> Easy | P6: =IF(UPPER(Legacy_Backup!O6)="YES","Visual","Text") -> Text | Q6: =PROPER(Legacy_Backup!O6) -> No | R6: =IF(UPPER(Legacy_Backup!O6)="YES",IF(Legacy_Backup!Y6<>"",Legacy_Backup!Y6,"Image required"),"NA") -> NA | S6: =IF(UPPER(Legacy_Backup!O6)="YES",IF(Legacy_Backup!Z6<>"",Legacy_Backup!Z6,"Prompt required"),"NA") -> NA | T6: =IF(Legacy_Backup!L6<>"",PROPER(Legacy_Backup!L6),"Apply") -> Evaluate | U6: =Legacy_Backup!P6 -> A team can spend its full budget making 100 keychains or first make 10 samples. What is the wiser approach? | V6: =Legacy_Backup!Q6 -> Make 10, collect feedback, then decide | W6: =Legacy_Backup!R6 -> Make 100 immediately to save time | X6: =Legacy_Backup!S6 -> Buy a machine before testing demand | Y6: =Legacy_Backup!T6 -> Avoid making anything until everyone agrees | Z6: =Legacy_Backup!U6 -> A | AA6: =Legacy_Backup!W6 -> Make 10, collect feedback, then decide is the best choice because it directly applies risk and decision making to the situation and addresses the stated need with a practical, responsible action. | AB6: =Legacy_Backup!X6 -> Builds practical entrepreneurship for future study, work and responsible citizenship. | AC6: =Legacy_Backup!M6 -> Entrepreneurship | AD6: =IF(UPPER(Legacy_Backup!O6)="YES",A6&".png","NA") -> NA | AE6: =Legacy_Backup!AB6 | AH6: =IF(LEFT(Legacy_Backup!AC6,1)="v",Legacy_Backup!AC6,"v"&Legacy_Backup!AC6) -> v1.0
A7: 08_EM_OS_006 | B7: 8 | C7: 1 | D7: Entrepreneurship Mindset | E7: EM | F7: 1 | G7: Opportunity Spotting | H7: OS | I7: OS-T02 | J7: =Legacy_Backup!G7 -> Product Innovation | K7: =TEXT(COUNTIF($E$2:E7,E7),"000") -> 006 | L7: =Legacy_Backup!H7 -> Improve an existing solution for user benefit | M7: =IFERROR(__xludf.DUMMYFUNCTION("IF(REGEXMATCH(UPPER(Legacy_Backup!I7),""KNOW""),""Know"",IF(REGEXMATCH(UPPER(Legacy_Backup!I7),""IMAGINE|INNOVATION""),""Imagine"",""Think""))"),"Imagine") -> Imagine | N7: =IFERROR(__xludf.DUMMYFUNCTION("IF(REGEXMATCH(UPPER(Legacy_Backup!J7),""FUTURE""),""Future-Oriented"",IF(REGEXMATCH(UPPER(Legacy_Backup!J7),""KNOWLEDGE""),""Knowledge-Based"",IF(REGEXMATCH(UPPER(Legacy_Backup!J7),""DECISION""),""Decision-Making"",""Situation-Based"")))"),"Situation-Based") -> Situation-Based | O7: =IF(UPPER(Legacy_Backup!K7)="HARD","Difficult",PROPER(Legacy_Backup!K7)) -> Easy | P7: =IF(UPPER(Legacy_Backup!O7)="YES","Visual","Text") -> Text | Q7: =PROPER(Legacy_Backup!O7) -> No | R7: =IF(UPPER(Legacy_Backup!O7)="YES",IF(Legacy_Backup!Y7<>"",Legacy_Backup!Y7,"Image required"),"NA") -> NA | S7: =IF(UPPER(Legacy_Backup!O7)="YES",IF(Legacy_Backup!Z7<>"",Legacy_Backup!Z7,"Prompt required"),"NA") -> NA | T7: =IF(Legacy_Backup!L7<>"",PROPER(Legacy_Backup!L7),"Apply") -> Create | U7: =Legacy_Backup!P7 -> Students regularly forget to water classroom plants. Which idea is both innovative and practical? | V7: =Legacy_Backup!Q7 -> A poster saying plants need water | W7: =Legacy_Backup!R7 -> A low-cost moisture (dryness) indicator for soil | X7: =Legacy_Backup!S7 -> Replacing plants with plastic ones | Y7: =Legacy_Backup!T7 -> Asking one student to remember forever | Z7: =Legacy_Backup!U7 -> B | AA7: =Legacy_Backup!W7 -> A low-cost moisture indicator that changes colour when soil is dry is the best choice because it directly applies product innovation to the situation and addresses the stated need with a practical, responsible action. | AB7: =Legacy_Backup!X7 -> Builds practical entrepreneurship for future study, work and responsible citizenship. | AC7: =Legacy_Backup!M7 -> Entrepreneurship | AD7: =IF(UPPER(Legacy_Backup!O7)="YES",A7&".png","NA") -> NA | AE7: =Legacy_Backup!AB7 | AH7: =IF(LEFT(Legacy_Backup!AC7,1)="v",Legacy_Backup!AC7,"v"&Legacy_Backup!AC7) -> v1.0
A8: 08_EM_EF_007 | B8: 8 | C8: 1 | D8: Entrepreneurship Mindset | E8: EM | F8: 7 | G8: Ethics, Integrity, and Fairness | H8: EF | I8: EF-T01 | J8: =Legacy_Backup!G8 -> Ethics and Fairness | K8: =TEXT(COUNTIF($E$2:E8,E8),"000") -> 007 | L8: =Legacy_Backup!H8 -> Choose honest business behaviour | M8: =IFERROR(__xludf.DUMMYFUNCTION("IF(REGEXMATCH(UPPER(Legacy_Backup!I8),""KNOW""),""Know"",IF(REGEXMATCH(UPPER(Legacy_Backup!I8),""IMAGINE|INNOVATION""),""Imagine"",""Think""))"),"Think") -> Think | N8: =IFERROR(__xludf.DUMMYFUNCTION("IF(REGEXMATCH(UPPER(Legacy_Backup!J8),""FUTURE""),""Future-Oriented"",IF(REGEXMATCH(UPPER(Legacy_Backup!J8),""KNOWLEDGE""),""Knowledge-Based"",IF(REGEXMATCH(UPPER(Legacy_Backup!J8),""DECISION""),""Decision-Making"",""Situation-Based"")))"),"Situation-Based") -> Situation-Based | O8: =IF(UPPER(Legacy_Backup!K8)="HARD","Difficult",PROPER(Legacy_Backup!K8)) -> Easy | P8: =IF(UPPER(Legacy_Backup!O8)="YES","Visual","Text") -> Text | Q8: =PROPER(Legacy_Backup!O8) -> No | R8: =IF(UPPER(Legacy_Backup!O8)="YES",IF(Legacy_Backup!Y8<>"",Legacy_Backup!Y8,"Image required"),"NA") -> NA | S8: =IF(UPPER(Legacy_Backup!O8)="YES",IF(Legacy_Backup!Z8<>"",Legacy_Backup!Z8,"Prompt required"),"NA") -> NA | T8: =IF(Legacy_Backup!L8<>"",PROPER(Legacy_Backup!L8),"Apply") -> Apply | U8: =Legacy_Backup!P8 -> A seller notices that one batch of notebooks has weak binding. What should the seller do? | V8: =Legacy_Backup!Q8 -> Hide the problem with new covers | W8: =Legacy_Backup!R8 -> Sell them quickly to younger students | X8: =Legacy_Backup!S8 -> Tell buyers and replace the faulty notebooks | Y8: =Legacy_Backup!T8 -> Increase the price to appear premium | Z8: =Legacy_Backup!U8 -> C | AA8: =Legacy_Backup!W8 -> Tell buyers and replace or discount the faulty notebooks is the best choice because it directly applies ethics and fairness to the situation and addresses the stated need with a practical, responsible action. | AB8: =Legacy_Backup!X8 -> Builds practical entrepreneurship for future study, work and responsible citizenship. | AC8: =Legacy_Backup!M8 -> Entrepreneurship | AD8: =IF(UPPER(Legacy_Backup!O8)="YES",A8&".png","NA") -> NA | AE8: =Legacy_Backup!AB8 | AH8: =IF(LEFT(Legacy_Backup!AC8,1)="v",Legacy_Backup!AC8,"v"&Legacy_Backup!AC8) -> v1.0
A9: 08_EM_BA_008 | B9: 8 | C9: 1 | D9: Entrepreneurship Mindset | E9: EM | F9: 9 | G9: Business Acumen – Profit, Loss & Pricing | H9: BA | I9: BA-T01 | J9: =Legacy_Backup!G9 -> Pricing and Profit | K9: =TEXT(COUNTIF($E$2:E9,E9),"000") -> 008 | L9: =Legacy_Backup!H9 -> Choose a price using cost and customer value | M9: =IFERROR(__xludf.DUMMYFUNCTION("IF(REGEXMATCH(UPPER(Legacy_Backup!I9),""KNOW""),""Know"",IF(REGEXMATCH(UPPER(Legacy_Backup!I9),""IMAGINE|INNOVATION""),""Imagine"",""Think""))"),"Think") -> Think | N9: =IFERROR(__xludf.DUMMYFUNCTION("IF(REGEXMATCH(UPPER(Legacy_Backup!J9),""FUTURE""),""Future-Oriented"",IF(REGEXMATCH(UPPER(Legacy_Backup!J9),""KNOWLEDGE""),""Knowledge-Based"",IF(REGEXMATCH(UPPER(Legacy_Backup!J9),""DECISION""),""Decision-Making"",""Situation-Based"")))"),"Situation-Based") -> Situation-Based | O9: =IF(UPPER(Legacy_Backup!K9)="HARD","Difficult",PROPER(Legacy_Backup!K9)) -> Easy | P9: =IF(UPPER(Legacy_Backup!O9)="YES","Visual","Text") -> Text | Q9: =PROPER(Legacy_Backup!O9) -> No | R9: =IF(UPPER(Legacy_Backup!O9)="YES",IF(Legacy_Backup!Y9<>"",Legacy_Backup!Y9,"Image required"),"NA") -> NA | S9: =IF(UPPER(Legacy_Backup!O9)="YES",IF(Legacy_Backup!Z9<>"",Legacy_Backup!Z9,"Prompt required"),"NA") -> NA | T9: =IF(Legacy_Backup!L9<>"",PROPER(Legacy_Backup!L9),"Apply") -> Analyze | U9: =Legacy_Backup!P9 -> A bookmark costs ₹12 to make. Students say they would comfortably pay ₹20. Which price is most reasonable for a small profit? | V9: =Legacy_Backup!Q9 -> ₹8 | W9: =Legacy_Backup!R9 -> ₹12 | X9: =Legacy_Backup!S9 -> ₹40 | Y9: =Legacy_Backup!T9 -> ₹18 | Z9: =Legacy_Backup!U9 -> D | AA9: =Legacy_Backup!W9 -> ₹18 is the best choice because it directly applies pricing and profit to the situation and addresses the stated need with a practical, responsible action. | AB9: =Legacy_Backup!X9 -> Builds practical entrepreneurship for future study, work and responsible citizenship. | AC9: =Legacy_Backup!M9 -> Entrepreneurship | AD9: =IF(UPPER(Legacy_Backup!O9)="YES",A9&".png","NA") -> NA | AE9: =Legacy_Backup!AB9 | AH9: =IF(LEFT(Legacy_Backup!AC9,1)="v",Legacy_Backup!AC9,"v"&Legacy_Backup!AC9) -> v1.0
A10: 08_EM_TC_009 | B10: 8 | C10: 1 | D10: Entrepreneurship Mindset | E10: EM | F10: 5 | G10: Teamwork and Communication | H10: TC | I10: TC-T01 | J10: =Legacy_Backup!G10 -> Teamwork and Communication | K10: =TEXT(COUNTIF($E$2:E10,E10),"000") -> 009 | L10: =Legacy_Backup!H10 -> Assign work according to team strengths | M10: =IFERROR(__xludf.DUMMYFUNCTION("IF(REGEXMATCH(UPPER(Legacy_Backup!I10),""KNOW""),""Know"",IF(REGEXMATCH(UPPER(Legacy_Backup!I10),""IMAGINE|INNOVATION""),""Imagine"",""Think""))"),"Think") -> Think | N10: =IFERROR(__xludf.DUMMYFUNCTION("IF(REGEXMATCH(UPPER(Legacy_Backup!J10),""FUTURE""),""Future-Oriented"",IF(REGEXMATCH(UPPER(Legacy_Backup!J10),""KNOWLEDGE""),""Knowledge-Based"",IF(REGEXMATCH(UPPER(Legacy_Backup!J10),""DECISION""),""Decision-Making"",""Situation-Based"")))"),"Situation-Based") -> Situation-Based | O10: =IF(UPPER(Legacy_Backup!K10)="HARD","Difficult",PROPER(Legacy_Backup!K10)) -> Easy | P10: =IF(UPPER(Legacy_Backup!O10)="YES","Visual","Text") -> Visual | Q10: =PROPER(Legacy_Backup!O10) -> Yes | R10: =IF(UPPER(Legacy_Backup!O10)="YES",IF(Legacy_Backup!Y10<>"",Legacy_Backup!Y10,"Image required"),"NA") -> A clean Grade 8 educational table or chart illustrating: The team chart shows: Aman—drawing, Beena—speaking, Charu—calculations, Dev—organising. Who should present the final pitch? | S10: =IF(UPPER(Legacy_Backup!O10)="YES",IF(Legacy_Backup!Z10<>"",Legacy_Backup!Z10,"Prompt required"),"NA") -> Create a clear, age-appropriate educational visual for Grade 8. Show only the information needed for this MCQ: The team chart shows: Aman—drawing, Beena—speaking, Charu—calculations, Dev—organising. Who should present the final pitch? Use a light background, simple labels, high contrast, no answer clues, landscape 4:3. | T10: =IF(Legacy_Backup!L10<>"",PROPER(Legacy_Backup!L10),"Apply") -> Analyze | U10: =Legacy_Backup!P10 -> The team chart shows: Aman—drawing, Beena—speaking, Charu—calculations, Dev—organising. Who should present the final pitch? | V10: =Legacy_Backup!Q10 -> Beena | W10: =Legacy_Backup!R10 -> Aman | X10: =Legacy_Backup!S10 -> Charu | Y10: =Legacy_Backup!T10 -> Dev | Z10: =Legacy_Backup!U10 -> A | AA10: =Legacy_Backup!W10 -> Beena is the best choice because it directly applies teamwork and communication to the situation and addresses the stated need with a practical, responsible action. | AB10: =Legacy_Backup!X10 -> Builds practical entrepreneurship for future study, work and responsible citizenship. | AC10: =Legacy_Backup!M10 -> Entrepreneurship | AD10: =IF(UPPER(Legacy_Backup!O10)="YES",A10&".png","NA") -> 08_EM_TC_009.png | AE10: =Legacy_Backup!AB10 | AH10: =IF(LEFT(Legacy_Backup!AC10,1)="v",Legacy_Backup!AC10,"v"&Legacy_Backup!AC10) -> v1.0
A11: 08_EM_OI_010 | B11: 8 | C11: 1 | D11: Entrepreneurship Mindset | E11: EM | F11: 2 | G11: Ownership and Initiative | H11: OI | I11: OI-T01 | J11: =Legacy_Backup!G11 -> Ownership and Initiative | K11: =TEXT(COUNTIF($E$2:E11,E11),"000") -> 010 | L11: =Legacy_Backup!H11 -> Demonstrate initiative when a plan faces a barrier | M11: =IFERROR(__xludf.DUMMYFUNCTION("IF(REGEXMATCH(UPPER(Legacy_Backup!I11),""KNOW""),""Know"",IF(REGEXMATCH(UPPER(Legacy_Backup!I11),""IMAGINE|INNOVATION""),""Imagine"",""Think""))"),"Think") -> Think | N11: =IFERROR(__xludf.DUMMYFUNCTION("IF(REGEXMATCH(UPPER(Legacy_Backup!J11),""FUTURE""),""Future-Oriented"",IF(REGEXMATCH(UPPER(Legacy_Backup!J11),""KNOWLEDGE""),""Knowledge-Based"",IF(REGEXMATCH(UPPER(Legacy_Backup!J11),""DECISION""),""Decision-Making"",""Situation-Based"")))"),"Situation-Based") -> Situation-Based | O11: =IF(UPPER(Legacy_Backup!K11)="HARD","Difficult",PROPER(Legacy_Backup!K11)) -> Easy | P11: =IF(UPPER(Legacy_Backup!O11)="YES","Visual","Text") -> Visual | Q11: =PROPER(Legacy_Backup!O11) -> Yes | R11: =IF(UPPER(Legacy_Backup!O11)="YES",IF(Legacy_Backup!Y11<>"",Legacy_Backup!Y11,"Image required"),"NA") -> A clean Grade 8 educational real-life scene illustrating: A venue cancels one day before a student sale. What should the team leader do first? | S11: =IF(UPPER(Legacy_Backup!O11)="YES",IF(Legacy_Backup!Z11<>"",Legacy_Backup!Z11,"Prompt required"),"NA") -> Create a clear, age-appropriate educational visual for Grade 8. Show only the information needed for this MCQ: A venue cancels one day before a student sale. What should the team leader do first? Use a light background, simple labels, high contrast, no answer clues, landscape 4:3. | T11: =IF(Legacy_Backup!L11<>"",PROPER(Legacy_Backup!L11),"Apply") -> Analyze | U11: =Legacy_Backup!P11 -> A venue cancels one day before a student sale. What should the team leader do first? | V11: =Legacy_Backup!Q11 -> Wait for someone else to solve it | W11: =Legacy_Backup!R11 -> Quickly identify another safe venue | X11: =Legacy_Backup!S11 -> Cancel without telling customers | Y11: =Legacy_Backup!T11 -> Blame the venue online | Z11: =Legacy_Backup!U11 -> B | AA11: =Legacy_Backup!W11 -> Quickly identify another safe venue and inform everyone is the best choice because it directly applies ownership and initiative to the situation and addresses the stated need with a practical, responsible action. | AB11: =Legacy_Backup!X11 -> Builds practical entrepreneurship for future study, work and responsible citizenship. | AC11: =Legacy_Backup!M11 -> Entrepreneurship | AD11: =IF(UPPER(Legacy_Backup!O11)="YES",A11&".png","NA") -> 08_EM_OI_010.png | AE11: =Legacy_Backup!AB11 | AH11: =IF(LEFT(Legacy_Backup!AC11,1)="v",Legacy_Backup!AC11,"v"&Legacy_Backup!AC11) -> v1.0
A12: 08_EM_CE_011 | B12: 8 | C12: 1 | D12: Entrepreneurship Mindset | E12: EM | F12: 6 | G12: Customer Understanding and Empathy | H12: CE | I12: CE-T03 | J12: =Legacy_Backup!G12 -> Customer Understanding | K12: =TEXT(COUNTIF($E$2:E12,E12),"000") -> 011 | L12: =Legacy_Backup!H12 -> Improve a product using evidence | M12: =IFERROR(__xludf.DUMMYFUNCTION("IF(REGEXMATCH(UPPER(Legacy_Backup!I12),""KNOW""),""Know"",IF(REGEXMATCH(UPPER(Legacy_Backup!I12),""IMAGINE|INNOVATION""),""Imagine"",""Think""))"),"Think") -> Think | N12: =IFERROR(__xludf.DUMMYFUNCTION("IF(REGEXMATCH(UPPER(Legacy_Backup!J12),""FUTURE""),""Future-Oriented"",IF(REGEXMATCH(UPPER(Legacy_Backup!J12),""KNOWLEDGE""),""Knowledge-Based"",IF(REGEXMATCH(UPPER(Legacy_Backup!J12),""DECISION""),""Decision-Making"",""Situation-Based"")))"),"Situation-Based") -> Situation-Based | O12: =IF(UPPER(Legacy_Backup!K12)="HARD","Difficult",PROPER(Legacy_Backup!K12)) -> Easy | P12: =IF(UPPER(Legacy_Backup!O12)="YES","Visual","Text") -> Text | Q12: =PROPER(Legacy_Backup!O12) -> No | R12: =IF(UPPER(Legacy_Backup!O12)="YES",IF(Legacy_Backup!Y12<>"",Legacy_Backup!Y12,"Image required"),"NA") -> NA | S12: =IF(UPPER(Legacy_Backup!O12)="YES",IF(Legacy_Backup!Z12<>"",Legacy_Backup!Z12,"Prompt required"),"NA") -> NA | T12: =IF(Legacy_Backup!L12<>"",PROPER(Legacy_Backup!L12),"Apply") -> Evaluate | U12: =Legacy_Backup!P12 -> After testing a pencil grip, 8 of 10 students say it slips. What is the best next step? | V12: =Legacy_Backup!Q12 -> Ignore them because two students liked it | W12: =Legacy_Backup!R12 -> Produce 500 grips immediately | X12: =Legacy_Backup!S12 -> Change the material and test the new version | Y12: =Legacy_Backup!T12 -> Change only the logo | Z12: =Legacy_Backup!U12 -> C | AA12: =Legacy_Backup!W12 -> Change the material and test the new version is the best choice because it directly applies customer understanding to the situation and addresses the stated need with a practical, responsible action. | AB12: =Legacy_Backup!X12 -> Builds practical entrepreneurship for future study, work and responsible citizenship. | AC12: =Legacy_Backup!M12 -> Entrepreneurship | AD12: =IF(UPPER(Legacy_Backup!O12)="YES",A12&".png","NA") -> NA | AE12: =Legacy_Backup!AB12 | AH12: =IF(LEFT(Legacy_Backup!AC12,1)="v",Legacy_Backup!AC12,"v"&Legacy_Backup!AC12) -> v1.0
A13: 08_EM_CE_012 | B13: 8 | C13: 1 | D13: Entrepreneurship Mindset | E13: EM | F13: 6 | G13: Customer Understanding and Empathy | H13: CE | I13: CE-T04 | J13: =Legacy_Backup!G13 -> Visual – shopkeeper talking | K13: =TEXT(COUNTIF($E$2:E13,E13),"000") -> 012 | L13: =Legacy_Backup!H13 -> Identify customer understanding from a visual scene. | M13: =IFERROR(__xludf.DUMMYFUNCTION("IF(REGEXMATCH(UPPER(Legacy_Backup!I13),""KNOW""),""Know"",IF(REGEXMATCH(UPPER(Legacy_Backup!I13),""IMAGINE|INNOVATION""),""Imagine"",""Think""))"),"Think") -> Think | N13: =IFERROR(__xludf.DUMMYFUNCTION("IF(REGEXMATCH(UPPER(Legacy_Backup!J13),""FUTURE""),""Future-Oriented"",IF(REGEXMATCH(UPPER(Legacy_Backup!J13),""KNOWLEDGE""),""Knowledge-Based"",IF(REGEXMATCH(UPPER(Legacy_Backup!J13),""DECISION""),""Decision-Making"",""Situation-Based"")))"),"Situation-Based") -> Situation-Based | O13: =IF(UPPER(Legacy_Backup!K13)="HARD","Difficult",PROPER(Legacy_Backup!K13)) -> Medium | P13: =IF(UPPER(Legacy_Backup!O13)="YES","Visual","Text") -> Visual | Q13: =PROPER(Legacy_Backup!O13) -> Yes | R13: =IF(UPPER(Legacy_Backup!O13)="YES",IF(Legacy_Backup!Y13<>"",Legacy_Backup!Y13,"Image required"),"NA") -> Shopkeeper speaking with a customer and noting something on a pad. | S13: =IF(UPPER(Legacy_Backup!O13)="YES",IF(Legacy_Backup!Z13<>"",Legacy_Backup!Z13,"Prompt required"),"NA") -> Draw a small shop with a shopkeeper listening to a customer, writing notes on a notepad. Show them facing each other. | T13: =IF(Legacy_Backup!L13<>"",PROPER(Legacy_Backup!L13),"Apply") -> Analyze | U13: =Legacy_Backup!P13 -> A shopkeeper listens to a customer and writes notes. What is this most likely showing? | V13: =Legacy_Backup!Q13 -> Understanding customer needs | W13: =Legacy_Backup!R13 -> Preparing to-do task list for customer | X13: =Legacy_Backup!S13 -> Preparing to close the shop forever | Y13: =Legacy_Backup!T13 -> Counting old stock without any reason | Z13: =Legacy_Backup!U13 -> A | AA13: =Legacy_Backup!W13 -> Listening and noting details suggests the shopkeeper is learning about customer needs. | AB13: =Legacy_Backup!X13 -> Normalises feedback collection as part of everyday business. | AC13: =Legacy_Backup!M13 -> Observing customer interaction. | AD13: =IF(UPPER(Legacy_Backup!O13)="YES",A13&".png","NA") -> 08_EM_CE_012.png | AE13: =Legacy_Backup!AB13 | AH13: =IF(LEFT(Legacy_Backup!AC13,1)="v",Legacy_Backup!AC13,"v"&Legacy_Backup!AC13) -> v1.0
A14: 08_EM_EF_013 | B14: 8 | C14: 1 | D14: Entrepreneurship Mindset | E14: EM | F14: 7 | G14: Ethics, Integrity, and Fairness | H14: EF | I14: EF-T02 | J14: =Legacy_Backup!G14 -> Visual – two students sharing | K14: =TEXT(COUNTIF($E$2:E14,E14),"000") -> 013 | L14: =Legacy_Backup!H14 -> Identify fairness in a simple sharing situation. | M14: =IFERROR(__xludf.DUMMYFUNCTION("IF(REGEXMATCH(UPPER(Legacy_Backup!I14),""KNOW""),""Know"",IF(REGEXMATCH(UPPER(Legacy_Backup!I14),""IMAGINE|INNOVATION""),""Imagine"",""Think""))"),"Know") -> Know | N14: =IFERROR(__xludf.DUMMYFUNCTION("IF(REGEXMATCH(UPPER(Legacy_Backup!J14),""FUTURE""),""Future-Oriented"",IF(REGEXMATCH(UPPER(Legacy_Backup!J14),""KNOWLEDGE""),""Knowledge-Based"",IF(REGEXMATCH(UPPER(Legacy_Backup!J14),""DECISION""),""Decision-Making"",""Situation-Based"")))"),"Situation-Based") -> Situation-Based | O14: =IF(UPPER(Legacy_Backup!K14)="HARD","Difficult",PROPER(Legacy_Backup!K14)) -> Medium | P14: =IF(UPPER(Legacy_Backup!O14)="YES","Visual","Text") -> Visual | Q14: =PROPER(Legacy_Backup!O14) -> Yes | R14: =IF(UPPER(Legacy_Backup!O14)="YES",IF(Legacy_Backup!Y14<>"",Legacy_Backup!Y14,"Image required"),"NA") -> Two students sharing equal parts of a snack. | S14: =IF(UPPER(Legacy_Backup!O14)="YES",IF(Legacy_Backup!Z14<>"",Legacy_Backup!Z14,"Prompt required"),"NA") -> Draw two students splitting a snack into equal parts and smiling. | T14: =IF(Legacy_Backup!L14<>"",PROPER(Legacy_Backup!L14),"Apply") -> Apply | U14: =Legacy_Backup!P14 -> Look at the image shpwing two friends What does this show? | V14: =Legacy_Backup!Q14 -> Fair sharing between friends | W14: =Legacy_Backup!R14 -> Debating on the choice of snack | X14: =Legacy_Backup!S14 -> Fighting over marks | Y14: =Legacy_Backup!T14 -> Ignoring each other completely | Z14: =Legacy_Backup!U14 -> A | AA14: =Legacy_Backup!W14 -> Equal division of a snack reflects fairness and consideration. | AB14: =Legacy_Backup!X14 -> Connects everyday fairness with ethical thinking in business. | AC14: =Legacy_Backup!M14 -> Everyday fairness. | AD14: =IF(UPPER(Legacy_Backup!O14)="YES",A14&".png","NA") -> 08_EM_EF_013.png | AE14: =Legacy_Backup!AB14 | AH14: =IF(LEFT(Legacy_Backup!AC14,1)="v",Legacy_Backup!AC14,"v"&Legacy_Backup!AC14) -> v1.0
A15: 08_PSI_PC_001 | B15: 8 | C15: 5 | D15: Problem Solving & Innovation | E15: PSI | F15: 25 | G15: Problem Solving with Creativity | H15: PC | I15: PC-T01 | J15: =Legacy_Backup!G15 -> Root Cause Analysis | K15: =TEXT(COUNTIF($E$2:E15,E15),"000") -> 001 | L15: =Legacy_Backup!H15 -> Identify causes before selecting solutions | M15: =IFERROR(__xludf.DUMMYFUNCTION("IF(REGEXMATCH(UPPER(Legacy_Backup!I15),""KNOW""),""Know"",IF(REGEXMATCH(UPPER(Legacy_Backup!I15),""IMAGINE|INNOVATION""),""Imagine"",""Think""))"),"Think") -> Think | N15: =IFERROR(__xludf.DUMMYFUNCTION("IF(REGEXMATCH(UPPER(Legacy_Backup!J15),""FUTURE""),""Future-Oriented"",IF(REGEXMATCH(UPPER(Legacy_Backup!J15),""KNOWLEDGE""),""Knowledge-Based"",IF(REGEXMATCH(UPPER(Legacy_Backup!J15),""DECISION""),""Decision-Making"",""Situation-Based"")))"),"Situation-Based") -> Situation-Based | O15: =IF(UPPER(Legacy_Backup!K15)="HARD","Difficult",PROPER(Legacy_Backup!K15)) -> Easy | P15: =IF(UPPER(Legacy_Backup!O15)="YES","Visual","Text") -> Text | Q15: =PROPER(Legacy_Backup!O15) -> No | R15: =IF(UPPER(Legacy_Backup!O15)="YES",IF(Legacy_Backup!Y15<>"",Legacy_Backup!Y15,"Image required"),"NA") -> NA | S15: =IF(UPPER(Legacy_Backup!O15)="YES",IF(Legacy_Backup!Z15<>"",Legacy_Backup!Z15,"Prompt required"),"NA") -> NA | T15: =IF(Legacy_Backup!L15<>"",PROPER(Legacy_Backup!L15),"Apply") -> Analyze | U15: =Legacy_Backup!P15 -> The school bus is late on four days. What should students do first? | V15: =Legacy_Backup!Q15 -> Meet the administration & request a new bus immediately | W15: =Legacy_Backup!R15 -> Record departure times, routes and delay reasons | X15: =Legacy_Backup!S15 -> Assume the driver is careless and seek change | Y15: =Legacy_Backup!T15 -> Cancel the bus service for students | Z15: =Legacy_Backup!U15 -> B | AA15: =Legacy_Backup!W15 -> Record departure times, routes and delay reasons is the best choice because it directly applies root cause analysis to the situation and addresses the stated need with a practical, responsible action. | AB15: =Legacy_Backup!X15 -> Builds practical problem solving for future study, work and responsible citizenship. | AC15: =Legacy_Backup!M15 -> Problem Solving | AD15: =IF(UPPER(Legacy_Backup!O15)="YES",A15&".png","NA") -> NA | AE15: =Legacy_Backup!AB15 | AH15: =IF(LEFT(Legacy_Backup!AC15,1)="v",Legacy_Backup!AC15,"v"&Legacy_Backup!AC15) -> v1.0
A16: 08_PSI_PC_002 | B16: 8 | C16: 5 | D16: Problem Solving & Innovation | E16: PSI | F16: 25 | G16: Problem Solving with Creativity | H16: PC | I16: PC-T02 | J16: =Legacy_Backup!G16 -> Prioritisation | K16: =TEXT(COUNTIF($E$2:E16,E16),"000") -> 002 | L16: =Legacy_Backup!H16 -> Prioritise a safety-critical issue | M16: =IFERROR(__xludf.DUMMYFUNCTION("IF(REGEXMATCH(UPPER(Legacy_Backup!I16),""KNOW""),""Know"",IF(REGEXMATCH(UPPER(Legacy_Backup!I16),""IMAGINE|INNOVATION""),""Imagine"",""Think""))"),"Think") -> Think | N16: =IFERROR(__xludf.DUMMYFUNCTION("IF(REGEXMATCH(UPPER(Legacy_Backup!J16),""FUTURE""),""Future-Oriented"",IF(REGEXMATCH(UPPER(Legacy_Backup!J16),""KNOWLEDGE""),""Knowledge-Based"",IF(REGEXMATCH(UPPER(Legacy_Backup!J16),""DECISION""),""Decision-Making"",""Situation-Based"")))"),"Situation-Based") -> Situation-Based | O16: =IF(UPPER(Legacy_Backup!K16)="HARD","Difficult",PROPER(Legacy_Backup!K16)) -> Easy | P16: =IF(UPPER(Legacy_Backup!O16)="YES","Visual","Text") -> Visual | Q16: =PROPER(Legacy_Backup!O16) -> Yes | R16: =IF(UPPER(Legacy_Backup!O16)="YES",IF(Legacy_Backup!Y16<>"",Legacy_Backup!Y16,"Image required"),"NA") -> A clean Grade 8 educational table or chart illustrating: A team lists four issues: faded poster, loose electric wire, slow Wi-Fi and untidy shelf. Which should be solved first? | S16: =IF(UPPER(Legacy_Backup!O16)="YES",IF(Legacy_Backup!Z16<>"",Legacy_Backup!Z16,"Prompt required"),"NA") -> Create a clear, age-appropriate educational visual for Grade 8. Show only the information needed for this MCQ: A team lists four issues: faded poster, loose electric wire, slow Wi-Fi and untidy shelf. Which should be solved first? Use a light background, simple labels, high contrast, no answer clues, landscape 4:3. | T16: =IF(Legacy_Backup!L16<>"",PROPER(Legacy_Backup!L16),"Apply") -> Analyze | U16: =Legacy_Backup!P16 -> A team lists four issues: faded poster, loose electric wire, slow Wi-Fi and untidy shelf. Which should be solved first? | V16: =Legacy_Backup!Q16 -> Faded poster | W16: =Legacy_Backup!R16 -> Slow Wi-Fi | X16: =Legacy_Backup!S16 -> Loose electric wire | Y16: =Legacy_Backup!T16 -> Untidy shelf | Z16: =Legacy_Backup!U16 -> C | AA16: =Legacy_Backup!W16 -> Loose electric wire is the best choice because it directly applies prioritisation to the situation and addresses the stated need with a practical, responsible action. | AB16: =Legacy_Backup!X16 -> Builds practical problem solving for future study, work and responsible citizenship. | AC16: =Legacy_Backup!M16 -> Problem Solving | AD16: =IF(UPPER(Legacy_Backup!O16)="YES",A16&".png","NA") -> 08_PSI_PC_002.png | AE16: =Legacy_Backup!AB16 | AH16: =IF(LEFT(Legacy_Backup!AC16,1)="v",Legacy_Backup!AC16,"v"&Legacy_Backup!AC16) -> v1.0
A17: 08_PSI_DI_003 | B17: 8 | C17: 5 | D17: Problem Solving & Innovation | E17: PSI | F17: 29 | G17: Data-based Innovation | H17: DI | I17: DI-T01 | J17: =Legacy_Backup!G17 -> Data-based Problem Solving | K17: =TEXT(COUNTIF($E$2:E17,E17),"000") -> 003 | L17: =Legacy_Backup!H17 -> Use data to identify a pattern | M17: =IFERROR(__xludf.DUMMYFUNCTION("IF(REGEXMATCH(UPPER(Legacy_Backup!I17),""KNOW""),""Know"",IF(REGEXMATCH(UPPER(Legacy_Backup!I17),""IMAGINE|INNOVATION""),""Imagine"",""Think""))"),"Think") -> Think | N17: =IFERROR(__xludf.DUMMYFUNCTION("IF(REGEXMATCH(UPPER(Legacy_Backup!J17),""FUTURE""),""Future-Oriented"",IF(REGEXMATCH(UPPER(Legacy_Backup!J17),""KNOWLEDGE""),""Knowledge-Based"",IF(REGEXMATCH(UPPER(Legacy_Backup!J17),""DECISION""),""Decision-Making"",""Situation-Based"")))"),"Situation-Based") -> Situation-Based | O17: =IF(UPPER(Legacy_Backup!K17)="HARD","Difficult",PROPER(Legacy_Backup!K17)) -> Easy | P17: =IF(UPPER(Legacy_Backup!O17)="YES","Visual","Text") -> Visual | Q17: =PROPER(Legacy_Backup!O17) -> Yes | R17: =IF(UPPER(Legacy_Backup!O17)="YES",IF(Legacy_Backup!Y17<>"",Legacy_Backup!Y17,"Image required"),"NA") -> A clean Grade 8 educational real-life scene illustrating: A table shows library crowding: Monday 20, Tuesday 22, Wednesday 45, Thursday 21 students. Which day should get an extra librarian? | S17: =IF(UPPER(Legacy_Backup!O17)="YES",IF(Legacy_Backup!Z17<>"",Legacy_Backup!Z17,"Prompt required"),"NA") -> Create a clear, age-appropriate educational visual for Grade 8. Show only the information needed for this MCQ: A table shows library crowding: Monday 20, Tuesday 22, Wednesday 45, Thursday 21 students. Which day should get an extra librarian? Use a light background, simple labels, high contrast, no answer clues, landscape 4:3. | T17: =IF(Legacy_Backup!L17<>"",PROPER(Legacy_Backup!L17),"Apply") -> Analyze | U17: =Legacy_Backup!P17 -> A table shows library crowding on weekdays. Which day is best suited for an extra librarian? | V17: =Legacy_Backup!Q17 -> Monday | W17: =Legacy_Backup!R17 -> Tuesday | X17: =Legacy_Backup!S17 -> Thursday | Y17: =Legacy_Backup!T17 -> Wednesday | Z17: =Legacy_Backup!U17 -> D | AA17: =Legacy_Backup!W17 -> Wednesday is the best choice because it directly applies data-based problem solving to the situation and addresses the stated need with a practical, responsible action. | AB17: =Legacy_Backup!X17 -> Builds practical problem solving for future study, work and responsible citizenship. | AC17: =Legacy_Backup!M17 -> Problem Solving | AD17: =IF(UPPER(Legacy_Backup!O17)="YES",A17&".png","NA") -> 08_PSI_DI_003.png | AE17: =Legacy_Backup!AB17 | AH17: =IF(LEFT(Legacy_Backup!AC17,1)="v",Legacy_Backup!AC17,"v"&Legacy_Backup!AC17) -> v1.0
A18: 08_PSI_DE_004 | B18: 8 | C18: 5 | D18: Problem Solving & Innovation | E18: PSI | F18: 28 | G18: Design Thinking & Ethics | H18: DE | I18: DE-T01 | J18: =Legacy_Backup!G18 -> Design Thinking | K18: =TEXT(COUNTIF($E$2:E18,E18),"000") -> 004 | L18: =Legacy_Backup!H18 -> Select a user-centred design improvement | M18: =IFERROR(__xludf.DUMMYFUNCTION("IF(REGEXMATCH(UPPER(Legacy_Backup!I18),""KNOW""),""Know"",IF(REGEXMATCH(UPPER(Legacy_Backup!I18),""IMAGINE|INNOVATION""),""Imagine"",""Think""))"),"Think") -> Think | N18: =IFERROR(__xludf.DUMMYFUNCTION("IF(REGEXMATCH(UPPER(Legacy_Backup!J18),""FUTURE""),""Future-Oriented"",IF(REGEXMATCH(UPPER(Legacy_Backup!J18),""KNOWLEDGE""),""Knowledge-Based"",IF(REGEXMATCH(UPPER(Legacy_Backup!J18),""DECISION""),""Decision-Making"",""Situation-Based"")))"),"Situation-Based") -> Situation-Based | O18: =IF(UPPER(Legacy_Backup!K18)="HARD","Difficult",PROPER(Legacy_Backup!K18)) -> Easy | P18: =IF(UPPER(Legacy_Backup!O18)="YES","Visual","Text") -> Text | Q18: =PROPER(Legacy_Backup!O18) -> No | R18: =IF(UPPER(Legacy_Backup!O18)="YES",IF(Legacy_Backup!Y18<>"",Legacy_Backup!Y18,"Image required"),"NA") -> NA | S18: =IF(UPPER(Legacy_Backup!O18)="YES",IF(Legacy_Backup!Z18<>"",Legacy_Backup!Z18,"Prompt required"),"NA") -> NA | T18: =IF(Legacy_Backup!L18<>"",PROPER(Legacy_Backup!L18),"Apply") -> Evaluate | U18: =Legacy_Backup!P18 -> A classroom dustbin has waste scattered around it, quite often. Which redesign best addresses the observed problem? | V18: =Legacy_Backup!Q18 -> A wider opening with clear labels | W18: =Legacy_Backup!R18 -> A taller decorative flag | X18: =Legacy_Backup!S18 -> A darker colour only | Y18: =Legacy_Backup!T18 -> A locked lid with a key | Z18: =Legacy_Backup!U18 -> A | AA18: =Legacy_Backup!W18 -> A wider opening with clear labels is the best choice because it directly applies design thinking to the situation and addresses the stated need with a practical, responsible action. | AB18: =Legacy_Backup!X18 -> Builds practical problem solving for future study, work and responsible citizenship. | AC18: =Legacy_Backup!M18 -> Problem Solving | AD18: =IF(UPPER(Legacy_Backup!O18)="YES",A18&".png","NA") -> NA | AE18: =Legacy_Backup!AB18 | AH18: =IF(LEFT(Legacy_Backup!AC18,1)="v",Legacy_Backup!AC18,"v"&Legacy_Backup!AC18) -> v1.0
A19: 08_PSI_PC_005 | B19: 8 | C19: 5 | D19: Problem Solving & Innovation | E19: PSI | F19: 25 | G19: Problem Solving with Creativity | H19: PC | I19: PC-T03 | J19: =Legacy_Backup!G19 -> Resource Allocation | K19: =TEXT(COUNTIF($E$2:E19,E19),"000") -> 005 | L19: =Legacy_Backup!H19 -> Use limited resources for maximum impact | M19: =IFERROR(__xludf.DUMMYFUNCTION("IF(REGEXMATCH(UPPER(Legacy_Backup!I19),""KNOW""),""Know"",IF(REGEXMATCH(UPPER(Legacy_Backup!I19),""IMAGINE|INNOVATION""),""Imagine"",""Think""))"),"Imagine") -> Imagine | N19: =IFERROR(__xludf.DUMMYFUNCTION("IF(REGEXMATCH(UPPER(Legacy_Backup!J19),""FUTURE""),""Future-Oriented"",IF(REGEXMATCH(UPPER(Legacy_Backup!J19),""KNOWLEDGE""),""Knowledge-Based"",IF(REGEXMATCH(UPPER(Legacy_Backup!J19),""DECISION""),""Decision-Making"",""Situation-Based"")))"),"Situation-Based") -> Situation-Based | O19: =IF(UPPER(Legacy_Backup!K19)="HARD","Difficult",PROPER(Legacy_Backup!K19)) -> Easy | P19: =IF(UPPER(Legacy_Backup!O19)="YES","Visual","Text") -> Text | Q19: =PROPER(Legacy_Backup!O19) -> No | R19: =IF(UPPER(Legacy_Backup!O19)="YES",IF(Legacy_Backup!Y19<>"",Legacy_Backup!Y19,"Image required"),"NA") -> NA | S19: =IF(UPPER(Legacy_Backup!O19)="YES",IF(Legacy_Backup!Z19<>"",Legacy_Backup!Z19,"Prompt required"),"NA") -> NA | T19: =IF(Legacy_Backup!L19<>"",PROPER(Legacy_Backup!L19),"Apply") -> Create | U19: =Legacy_Backup!P19 -> A team has ₹500 to reduce water waste. A tap washer costs ₹50 and fixes one leaking tap; a poster costs ₹100. Five taps leak. What should the team prioritise? | V19: =Legacy_Backup!Q19 -> Five posters | W19: =Legacy_Backup!R19 -> Repair the five leaking taps | X19: =Legacy_Backup!S19 -> One poster and no repairs | Y19: =Legacy_Backup!T19 -> Save all the money without acting | Z19: =Legacy_Backup!U19 -> B | AA19: =Legacy_Backup!W19 -> Repair the five leaking taps is the best choice because it directly applies resource allocation to the situation and addresses the stated need with a practical, responsible action. | AB19: =Legacy_Backup!X19 -> Builds practical problem solving for future study, work and responsible citizenship. | AC19: =Legacy_Backup!M19 -> Problem Solving | AD19: =IF(UPPER(Legacy_Backup!O19)="YES",A19&".png","NA") -> NA | AE19: =Legacy_Backup!AB19 | AH19: =IF(LEFT(Legacy_Backup!AC19,1)="v",Legacy_Backup!AC19,"v"&Legacy_Backup!AC19) -> v1.0
A20: 08_PSI_IA_006 | B20: 8 | C20: 5 | D20: Problem Solving & Innovation | E20: PSI | F20: 26 | G20: Innovation & Adaptability | H20: IA | I20: IA-T01 | J20: =Legacy_Backup!G20 -> Innovation and Adaptability | K20: =TEXT(COUNTIF($E$2:E20,E20),"000") -> 006 | L20: =Legacy_Backup!H20 -> Adapt a solution after testing | M20: =IFERROR(__xludf.DUMMYFUNCTION("IF(REGEXMATCH(UPPER(Legacy_Backup!I20),""KNOW""),""Know"",IF(REGEXMATCH(UPPER(Legacy_Backup!I20),""IMAGINE|INNOVATION""),""Imagine"",""Think""))"),"Think") -> Think | N20: =IFERROR(__xludf.DUMMYFUNCTION("IF(REGEXMATCH(UPPER(Legacy_Backup!J20),""FUTURE""),""Future-Oriented"",IF(REGEXMATCH(UPPER(Legacy_Backup!J20),""KNOWLEDGE""),""Knowledge-Based"",IF(REGEXMATCH(UPPER(Legacy_Backup!J20),""DECISION""),""Decision-Making"",""Situation-Based"")))"),"Situation-Based") -> Situation-Based | O20: =IF(UPPER(Legacy_Backup!K20)="HARD","Difficult",PROPER(Legacy_Backup!K20)) -> Easy | P20: =IF(UPPER(Legacy_Backup!O20)="YES","Visual","Text") -> Text | Q20: =PROPER(Legacy_Backup!O20) -> No | R20: =IF(UPPER(Legacy_Backup!O20)="YES",IF(Legacy_Backup!Y20<>"",Legacy_Backup!Y20,"Image required"),"NA") -> NA | S20: =IF(UPPER(Legacy_Backup!O20)="YES",IF(Legacy_Backup!Z20<>"",Legacy_Backup!Z20,"Prompt required"),"NA") -> NA | T20: =IF(Legacy_Backup!L20<>"",PROPER(Legacy_Backup!L20),"Apply") -> Apply | U20: =Legacy_Backup!P20 -> A cardboard phone stand bends during testing. Which change is most likely to improve it? | V20: =Legacy_Backup!Q20 -> Add more decoration | W20: =Legacy_Backup!R20 -> Use thinner cardboard | X20: =Legacy_Backup!S20 -> Add folded triangular supports | Y20: =Legacy_Backup!T20 -> Make the phone heavier | Z20: =Legacy_Backup!U20 -> C | AA20: =Legacy_Backup!W20 -> Add folded triangular supports is the best choice because it directly applies innovation and adaptability to the situation and addresses the stated need with a practical, responsible action. | AB20: =Legacy_Backup!X20 -> Builds practical problem solving for future study, work and responsible citizenship. | AC20: =Legacy_Backup!M20 -> Problem Solving | AD20: =IF(UPPER(Legacy_Backup!O20)="YES",A20&".png","NA") -> NA | AE20: =Legacy_Backup!AB20 | AH20: =IF(LEFT(Legacy_Backup!AC20,1)="v",Legacy_Backup!AC20,"v"&Legacy_Backup!AC20) -> v1.0
A21: 08_PSI_DI_007 | B21: 8 | C21: 5 | D21: Problem Solving & Innovation | E21: PSI | F21: 29 | G21: Data-based Innovation | H21: DI | I21: DI-T02 | J21: =Legacy_Backup!G21 -> Visual – bar chart of app usage | K21: =TEXT(COUNTIF($E$2:E21,E21),"000") -> 007 | L21: =Legacy_Backup!H21 -> Read a simple bar chart. | M21: =IFERROR(__xludf.DUMMYFUNCTION("IF(REGEXMATCH(UPPER(Legacy_Backup!I21),""KNOW""),""Know"",IF(REGEXMATCH(UPPER(Legacy_Backup!I21),""IMAGINE|INNOVATION""),""Imagine"",""Think""))"),"Think") -> Think | N21: =IFERROR(__xludf.DUMMYFUNCTION("IF(REGEXMATCH(UPPER(Legacy_Backup!J21),""FUTURE""),""Future-Oriented"",IF(REGEXMATCH(UPPER(Legacy_Backup!J21),""KNOWLEDGE""),""Knowledge-Based"",IF(REGEXMATCH(UPPER(Legacy_Backup!J21),""DECISION""),""Decision-Making"",""Situation-Based"")))"),"Situation-Based") -> Situation-Based | O21: =IF(UPPER(Legacy_Backup!K21)="HARD","Difficult",PROPER(Legacy_Backup!K21)) -> Medium | P21: =IF(UPPER(Legacy_Backup!O21)="YES","Visual","Text") -> Visual | Q21: =PROPER(Legacy_Backup!O21) -> Yes | R21: =IF(UPPER(Legacy_Backup!O21)="YES",IF(Legacy_Backup!Y21<>"",Legacy_Backup!Y21,"Image required"),"NA") -> Bar chart showing app usage increasing from Monday to Friday. | S21: =IF(UPPER(Legacy_Backup!O21)="YES",IF(Legacy_Backup!Z21<>"",Legacy_Backup!Z21,"Prompt required"),"NA") -> Create a bar chart with days Monday to Friday and usage values rising across the week. | T21: =IF(Legacy_Backup!L21<>"",PROPER(Legacy_Backup!L21),"Apply") -> Analyze | U21: =Legacy_Backup!P21 -> A bar chart shows a gaming app usage over a week. What does this suggest? | V21: =Legacy_Backup!Q21 -> More students use the app toward the end of the week | W21: =Legacy_Backup!R21 -> Students never use the app on week ends | X21: =Legacy_Backup!S21 -> The app only works on Friday | Y21: =Legacy_Backup!T21 -> The chart has no meaning as night data is not mentioned | Z21: =Legacy_Backup!U21 -> A | AA21: =Legacy_Backup!W21 -> The tallest bar shows the highest usage level. | AB21: =Legacy_Backup!X21 -> Helps students understand how charts support decisions. | AC21: =Legacy_Backup!M21 -> Interpreting visual data. | AD21: =IF(UPPER(Legacy_Backup!O21)="YES",A21&".png","NA") -> 08_PSI_DI_007.png | AE21: =Legacy_Backup!AB21 | AH21: =IF(LEFT(Legacy_Backup!AC21,1)="v",Legacy_Backup!AC21,"v"&Legacy_Backup!AC21) -> v1.0
A22: 08_PSI_PC_008 | B22: 8 | C22: 5 | D22: Problem Solving & Innovation | E22: PSI | F22: 25 | G22: Problem Solving with Creativity | H22: PC | I22: PC-T04 | J22: =Legacy_Backup!G22 -> Pattern Recognition | K22: =TEXT(COUNTIF($E$2:E22,E22),"000") -> 008 | L22: =Legacy_Backup!H22 -> Recognise a simple operational pattern | M22: =IFERROR(__xludf.DUMMYFUNCTION("IF(REGEXMATCH(UPPER(Legacy_Backup!I22),""KNOW""),""Know"",IF(REGEXMATCH(UPPER(Legacy_Backup!I22),""IMAGINE|INNOVATION""),""Imagine"",""Think""))"),"Think") -> Think | N22: =IFERROR(__xludf.DUMMYFUNCTION("IF(REGEXMATCH(UPPER(Legacy_Backup!J22),""FUTURE""),""Future-Oriented"",IF(REGEXMATCH(UPPER(Legacy_Backup!J22),""KNOWLEDGE""),""Knowledge-Based"",IF(REGEXMATCH(UPPER(Legacy_Backup!J22),""DECISION""),""Decision-Making"",""Situation-Based"")))"),"Situation-Based") -> Situation-Based | O22: =IF(UPPER(Legacy_Backup!K22)="HARD","Difficult",PROPER(Legacy_Backup!K22)) -> Easy | P22: =IF(UPPER(Legacy_Backup!O22)="YES","Visual","Text") -> Visual | Q22: =PROPER(Legacy_Backup!O22) -> Yes | R22: =IF(UPPER(Legacy_Backup!O22)="YES",IF(Legacy_Backup!Y22<>"",Legacy_Backup!Y22,"Image required"),"NA") -> A clean Grade 8 educational table or chart illustrating: A machine flashes colours in this order: red, blue, blue, red, blue, blue. What comes next if the pattern repeats? | S22: =IF(UPPER(Legacy_Backup!O22)="YES",IF(Legacy_Backup!Z22<>"",Legacy_Backup!Z22,"Prompt required"),"NA") -> Create a clear, age-appropriate educational visual for Grade 8. Show only the information needed for this MCQ: A machine flashes colours in this order: red, blue, blue, red, blue, blue. What comes next if the pattern repeats? Use a light background, simple labels, high contrast, no answer clues, landscape 4:3. | T22: =IF(Legacy_Backup!L22<>"",PROPER(Legacy_Backup!L22),"Apply") -> Analyze | U22: =Legacy_Backup!P22 -> A machine flashes colours in the order as shown in the image. What comes next if the pattern repeats? | V22: =Legacy_Backup!Q22 -> Red | W22: =Legacy_Backup!R22 -> Blue | X22: =Legacy_Backup!S22 -> Green | Y22: =Legacy_Backup!T22 -> Yellow | Z22: =Legacy_Backup!U22 -> A | AA22: =Legacy_Backup!W22 -> Red is the best choice because it directly applies pattern recognition to the situation and addresses the stated need with a practical, responsible action. | AB22: =Legacy_Backup!X22 -> Builds practical problem solving for future study, work and responsible citizenship. | AC22: =Legacy_Backup!M22 -> Problem Solving | AD22: =IF(UPPER(Legacy_Backup!O22)="YES",A22&".png","NA") -> 08_PSI_PC_008.png | AE22: =Legacy_Backup!AB22 | AH22: =IF(LEFT(Legacy_Backup!AC22,1)="v",Legacy_Backup!AC22,"v"&Legacy_Backup!AC22) -> v1.0
A23: 08_PSI_VT_009 | B23: 8 | C23: 5 | D23: Problem Solving & Innovation | E23: PSI | F23: 27 | G23: Validation & Trial | H23: VT | I23: VT-T01 | J23: =Legacy_Backup!G23 -> Validation and Trial | K23: =TEXT(COUNTIF($E$2:E23,E23),"000") -> 009 | L23: =Legacy_Backup!H23 -> Choose an appropriate prototype test | M23: =IFERROR(__xludf.DUMMYFUNCTION("IF(REGEXMATCH(UPPER(Legacy_Backup!I23),""KNOW""),""Know"",IF(REGEXMATCH(UPPER(Legacy_Backup!I23),""IMAGINE|INNOVATION""),""Imagine"",""Think""))"),"Think") -> Think | N23: =IFERROR(__xludf.DUMMYFUNCTION("IF(REGEXMATCH(UPPER(Legacy_Backup!J23),""FUTURE""),""Future-Oriented"",IF(REGEXMATCH(UPPER(Legacy_Backup!J23),""KNOWLEDGE""),""Knowledge-Based"",IF(REGEXMATCH(UPPER(Legacy_Backup!J23),""DECISION""),""Decision-Making"",""Situation-Based"")))"),"Situation-Based") -> Situation-Based | O23: =IF(UPPER(Legacy_Backup!K23)="HARD","Difficult",PROPER(Legacy_Backup!K23)) -> Easy | P23: =IF(UPPER(Legacy_Backup!O23)="YES","Visual","Text") -> Visual | Q23: =PROPER(Legacy_Backup!O23) -> Yes | R23: =IF(UPPER(Legacy_Backup!O23)="YES",IF(Legacy_Backup!Y23<>"",Legacy_Backup!Y23,"Image required"),"NA") -> A clean Grade 8 educational real-life scene illustrating: A team designs a low-cost reading lamp. Which test gives the most useful evidence? | S23: =IF(UPPER(Legacy_Backup!O23)="YES",IF(Legacy_Backup!Z23<>"",Legacy_Backup!Z23,"Prompt required"),"NA") -> Create a clear, age-appropriate educational visual for Grade 8. Show only the information needed for this MCQ: A team designs a low-cost reading lamp. Which test gives the most useful evidence? Use a light background, simple labels, high contrast, no answer clues, landscape 4:3. | T23: =IF(Legacy_Backup!L23<>"",PROPER(Legacy_Backup!L23),"Apply") -> Analyze | U23: =Legacy_Backup!P23 -> A team designs a low-cost reading lamp. Which test gives the most useful evidence? | V23: =Legacy_Backup!Q23 -> Ask the designer whether it looks good | W23: =Legacy_Backup!R23 -> Let several students use it and record findings | X23: =Legacy_Backup!S23 -> Count how many stickers are on it | Y23: =Legacy_Backup!T23 -> Compare its body colour with another lamp | Z23: =Legacy_Backup!U23 -> B | AA23: =Legacy_Backup!W23 -> Let several students use it and record brightness, stability and heat is the best choice because it directly applies validation and trial to the situation and addresses the stated need with a practical, responsible action. | AB23: =Legacy_Backup!X23 -> Builds practical problem solving for future study, work and responsible citizenship. | AC23: =Legacy_Backup!M23 -> Problem Solving | AD23: =IF(UPPER(Legacy_Backup!O23)="YES",A23&".png","NA") -> 08_PSI_VT_009.png | AE23: =Legacy_Backup!AB23 | AH23: =IF(LEFT(Legacy_Backup!AC23,1)="v",Legacy_Backup!AC23,"v"&Legacy_Backup!AC23) -> v1.0
A24: 08_PSI_PC_010 | B24: 8 | C24: 5 | D24: Problem Solving & Innovation | E24: PSI | F24: 25 | G24: Problem Solving with Creativity | H24: PC | I24: PC-T05 | J24: =Legacy_Backup!G24 -> Cause and Effect | K24: =TEXT(COUNTIF($E$2:E24,E24),"000") -> 010 | L24: =Legacy_Backup!H24 -> Separate symptoms from likely causes | M24: =IFERROR(__xludf.DUMMYFUNCTION("IF(REGEXMATCH(UPPER(Legacy_Backup!I24),""KNOW""),""Know"",IF(REGEXMATCH(UPPER(Legacy_Backup!I24),""IMAGINE|INNOVATION""),""Imagine"",""Think""))"),"Think") -> Think | N24: =IFERROR(__xludf.DUMMYFUNCTION("IF(REGEXMATCH(UPPER(Legacy_Backup!J24),""FUTURE""),""Future-Oriented"",IF(REGEXMATCH(UPPER(Legacy_Backup!J24),""KNOWLEDGE""),""Knowledge-Based"",IF(REGEXMATCH(UPPER(Legacy_Backup!J24),""DECISION""),""Decision-Making"",""Situation-Based"")))"),"Situation-Based") -> Situation-Based | O24: =IF(UPPER(Legacy_Backup!K24)="HARD","Difficult",PROPER(Legacy_Backup!K24)) -> Easy | P24: =IF(UPPER(Legacy_Backup!O24)="YES","Visual","Text") -> Text | Q24: =PROPER(Legacy_Backup!O24) -> No | R24: =IF(UPPER(Legacy_Backup!O24)="YES",IF(Legacy_Backup!Y24<>"",Legacy_Backup!Y24,"Image required"),"NA") -> NA | S24: =IF(UPPER(Legacy_Backup!O24)="YES",IF(Legacy_Backup!Z24<>"",Legacy_Backup!Z24,"Prompt required"),"NA") -> NA | T24: =IF(Legacy_Backup!L24<>"",PROPER(Legacy_Backup!L24),"Apply") -> Evaluate | U24: =Legacy_Backup!P24 -> A classroom becomes very hot every afternoon. What is the best way to investigate the cause? | V24: =Legacy_Backup!Q24 -> Buy new curtains and install AC | W24: =Legacy_Backup!R24 -> Move the class permanently to a new place | X24: =Legacy_Backup!S24 -> Measure ventilation and temperature at different times | Y24: =Legacy_Backup!T24 -> Switch off all lights for one minute to cool down | Z24: =Legacy_Backup!U24 -> C | AA24: =Legacy_Backup!W24 -> Measure sunlight, ventilation and temperature at different times is the best choice because it directly applies cause and effect to the situation and addresses the stated need with a practical, responsible action. | AB24: =Legacy_Backup!X24 -> Builds practical problem solving for future study, work and responsible citizenship. | AC24: =Legacy_Backup!M24 -> Problem Solving | AD24: =IF(UPPER(Legacy_Backup!O24)="YES",A24&".png","NA") -> NA | AE24: =Legacy_Backup!AB24 | AH24: =IF(LEFT(Legacy_Backup!AC24,1)="v",Legacy_Backup!AC24,"v"&Legacy_Backup!AC24) -> v1.0
A25: 08_PSI_PC_011 | B25: 8 | C25: 5 | D25: Problem Solving & Innovation | E25: PSI | F25: 25 | G25: Problem Solving with Creativity | H25: PC | I25: PC-T06 | J25: =Legacy_Backup!G25 -> Decision Making | K25: =TEXT(COUNTIF($E$2:E25,E25),"000") -> 011 | L25: =Legacy_Backup!H25 -> Compare alternatives using agreed criteria | M25: =IFERROR(__xludf.DUMMYFUNCTION("IF(REGEXMATCH(UPPER(Legacy_Backup!I25),""KNOW""),""Know"",IF(REGEXMATCH(UPPER(Legacy_Backup!I25),""IMAGINE|INNOVATION""),""Imagine"",""Think""))"),"Imagine") -> Imagine | N25: =IFERROR(__xludf.DUMMYFUNCTION("IF(REGEXMATCH(UPPER(Legacy_Backup!J25),""FUTURE""),""Future-Oriented"",IF(REGEXMATCH(UPPER(Legacy_Backup!J25),""KNOWLEDGE""),""Knowledge-Based"",IF(REGEXMATCH(UPPER(Legacy_Backup!J25),""DECISION""),""Decision-Making"",""Situation-Based"")))"),"Situation-Based") -> Situation-Based | O25: =IF(UPPER(Legacy_Backup!K25)="HARD","Difficult",PROPER(Legacy_Backup!K25)) -> Easy | P25: =IF(UPPER(Legacy_Backup!O25)="YES","Visual","Text") -> Text | Q25: =PROPER(Legacy_Backup!O25) -> No | R25: =IF(UPPER(Legacy_Backup!O25)="YES",IF(Legacy_Backup!Y25<>"",Legacy_Backup!Y25,"Image required"),"NA") -> NA | S25: =IF(UPPER(Legacy_Backup!O25)="YES",IF(Legacy_Backup!Z25<>"",Legacy_Backup!Z25,"Prompt required"),"NA") -> NA | T25: =IF(Legacy_Backup!L25<>"",PROPER(Legacy_Backup!L25),"Apply") -> Create | U25: =Legacy_Backup!P25 -> Three bridge models are scored out of 5: P—strength 5, cost 2; Q—strength 4, cost 4; R—strength 2, cost 5. If both strength and cost matter equally, which is the balanced choice? | V25: =Legacy_Backup!Q25 -> P | W25: =Legacy_Backup!R25 -> R | X25: =Legacy_Backup!S25 -> All are equal | Y25: =Legacy_Backup!T25 -> Q | Z25: =Legacy_Backup!U25 -> D | AA25: =Legacy_Backup!W25 -> Q is the best choice because it directly applies decision making to the situation and addresses the stated need with a practical, responsible action. | AB25: =Legacy_Backup!X25 -> Builds practical problem solving for future study, work and responsible citizenship. | AC25: =Legacy_Backup!M25 -> Problem Solving | AD25: =IF(UPPER(Legacy_Backup!O25)="YES",A25&".png","NA") -> NA | AE25: =Legacy_Backup!AB25 | AH25: =IF(LEFT(Legacy_Backup!AC25,1)="v",Legacy_Backup!AC25,"v"&Legacy_Backup!AC25) -> v1.0
